Traceback (most recent call last):
  File "/home/shengyuf/haohanl/LeanCOT/gpt-fast/cot_sample1.py", line 27, in <module>
    from lean_dojo import *
  File "/home/shengyuf/anaconda3/envs/lean/lib/python3.10/site-packages/lean_dojo/__init__.py", line 2, in <module>
    from .data_extraction.trace import (
  File "/home/shengyuf/anaconda3/envs/lean/lib/python3.10/site-packages/lean_dojo/data_extraction/trace.py", line 12, in <module>
    from .cache import cache
  File "/home/shengyuf/anaconda3/envs/lean/lib/python3.10/site-packages/lean_dojo/data_extraction/cache.py", line 105, in <module>
    cache = Cache(CACHE_DIR)
  File "<string>", line 4, in __init__
  File "/home/shengyuf/anaconda3/envs/lean/lib/python3.10/site-packages/lean_dojo/data_extraction/cache.py", line 58, in __post_init__
    self.cache_dir.mkdir(parents=True)
  File "/home/shengyuf/anaconda3/envs/lean/lib/python3.10/pathlib.py", line 1175, in mkdir
    self._accessor.mkdir(self, mode)
FileExistsError: [Errno 17] File exists: '/tmp/.cache/mathl'
